Workbook

Sheet Notes
A1: MXene basal plane vs FCC and L12 (111) lattice strain
A3: Strain (%) = 100 * (a_MXene - a_111) / a_111.
A4: a_111 = a_cubic / sqrt(2). For both FCC and L12 this is the nearest-neighbor spacing of the (111) hexagonal net.
A5: Positive strain: MXene cell is larger than the metal (111) net (MXene compressed in a coherent 1x1 cell).
A6: L12 columns are purple. Ni3Ti L12 is metastable (stable structure is D024). Fe3Al stable structure is D03; the L12-like a is approximate.
A7: Double-transition-metal rows are ordered out-of-plane M'2M''C2 unless marked carbonitride or solid solution.
A8: O-terminated rows are smaller than the matching bare carbide. Solid-solution rows are Vegard estimates.
A9: Blue/yellow cells on Metals and MXenes are inputs. Strain sheets are formulas.
A10: Color scale on Strain: blue = MXene smaller, white = 0, red = MXene larger. AbsStrain: green < 2%, yellow ~ 5%, red > 8%.

Sheet Metals
A1: FCC and L12 crystals — cubic a and (111) hexagonal spacing
A3: Symbol | B3: Name | C3: Structure | D3: a_cubic (A) | E3: a_111 (A) | F3: Source
A4: Ni | B4: Nickel | C4: FCC | D4: 3.5241 | E4: =D4/SQRT(2) -> 2.491915 | F4: exp RT
A5: Co | B5: Cobalt (FCC) | C5: FCC | D5: 3.5446 | E5: =D5/SQRT(2) -> 2.5064107 | F5: metastable FCC
A6: Cu | B6: Copper | C6: FCC | D6: 3.6149 | E6: =D6/SQRT(2) -> 2.5561203 | F6: exp RT
A7: Rh | B7: Rhodium | C7: FCC | D7: 3.8034 | E7: =D7/SQRT(2) -> 2.6894099 | F7: exp RT
A8: Ir | B8: Iridium | C8: FCC | D8: 3.8394 | E8: =D8/SQRT(2) -> 2.7148658 | F8: exp RT
A9: Pd | B9: Palladium | C9: FCC | D9: 3.8907 | E9: =D9/SQRT(2) -> 2.7511404 | F9: exp RT
A10: Pt | B10: Platinum | C10: FCC | D10: 3.9239 | E10: =D10/SQRT(2) -> 2.7746163 | F10: exp RT
A11: Al | B11: Aluminum | C11: FCC | D11: 4.0496 | E11: =D11/SQRT(2) -> 2.8634996 | F11: exp RT
A12: Au | B12: Gold | C12: FCC | D12: 4.0782 | E12: =D12/SQRT(2) -> 2.8837229 | F12: exp RT
A13: Ag | B13: Silver | C13: FCC | D13: 4.0853 | E13: =D13/SQRT(2) -> 2.8887433 | F13: exp RT
A14: Pb | B14: Lead | C14: FCC | D14: 4.9502 | E14: =D14/SQRT(2) -> 3.50032 | F14: exp RT
A15: Ni3Al | B15: Ni3Al | C15: L12 | D15: 3.572 | E15: =D15/SQRT(2) -> 2.5257854 | F15: exp RT, gamma-prime
... A27: Fe3Al | B27: Fe3Al (L12-like) | C27: L12 | D27: 3.65 | E27: =D27/SQRT(2) -> 2.5809398 | F27: approx; stable is D03 a~5.79

Sheet MXenes
A1: MXene in-plane lattice constants, including ordered double transition metals
A3: Formula | B3: Family | C3: Termination | D3: a (A) | E3: Source | F3: Row
A4: Ti2C | B4: single M2C | C4: none | D4: 3.039 | E4: DFT PBE, Yorulmaz 2020 | F4: 1
A5: V2C | B5: single M2C | C5: none | D5: 2.881 | E5: DFT PBE, Yorulmaz 2020 | F5: 2
A6: Cr2C | B6: single M2C | C6: none | D6: 2.825 | E6: DFT PBE, Yorulmaz 2020 | F6: 3
A7: Zr2C | B7: single M2C | C7: none | D7: 3.28 | E7: DFT PBE, Yorulmaz 2020 | F7: 4
A8: Nb2C | B8: single M2C | C8: none | D8: 3.104 | E8: DFT PBE, Yorulmaz 2020 | F8: 5
A9: Mo2C | B9: single M2C | C9: none | D9: 2.848 | E9: DFT PBE, Yorulmaz 2020; other PBE ~3.00 | F9: 6
A10: Hf2C | B10: single M2C | C10: none | D10: 3.195 | E10: DFT PBE, Yorulmaz 2020 | F10: 7
A11: Ta2C | B11: single M2C | C11: none | D11: 3.067 | E11: DFT PBE, Yorulmaz 2020 | F11: 8
A12: W2C | B12: single M2C | C12: none | D12: 2.847 | E12: DFT PBE, Yorulmaz 2020 | F12: 9
A13: Ti3C2 | B13: single M3C2 | C13: none | D13: 3.104 | E13: DFT PBE, Yorulmaz 2020 | F13: 10
A14: V3C2 | B14: single M3C2 | C14: none | D14: 2.96 | E14: DFT PBE, Yorulmaz 2020 | F14: 11
A15: Nb3C2 | B15: single M3C2 | C15: none | D15: 3.153 | E15: DFT PBE, Yorulmaz 2020 | F15: 12
... A49: Ti3C2Tx | B49: experimental | C49: O/F/OH | D49: 3.0505 | E49: PDF, Shi PRL 2014 | F49: 46

Sheet Strain
A1: Lattice strain delta (%) = 100*(a_MXene - a_111)/a_111
A2: Row 3 is a_111 (A). Column B is a_MXene (A). L12 metals start after Pb. Formulas read Metals and MXenes.
A3: a_111 (A) | D3: =Metals!E4 -> 2.491915 | E3: =Metals!E5 -> 2.5064107 | F3: =Metals!E6 -> 2.5561203 | G3: =Metals!E7 -> 2.6894099 | H3: =Metals!E8 -> 2.7148658 | I3: =Metals!E9 -> 2.7511404 | J3: =Metals!E10 -> 2.7746163 | K3: =Metals!E11 -> 2.8634996 | L3: =Metals!E12 -> 2.8837229 | M3: =Metals!E13 -> 2.8887433 | N3: =Metals!E14 -> 3.50032 | O3: =Metals!E15 -> 2.5257854 | P3: =Metals!E16 -> 2.5286138 | Q3: =Metals!E17 -> 2.4777022 | R3: =Metals!E18 -> 2.5137646 | S3: =Metals!E19 -> 2.5378062 | T3: =Metals!E20 -> 2.5781113 | U3: =Metals!E21 -> 2.5526555 | V3: =Metals!E22 -> 2.5314423 | W3: =Metals!E23 -> 2.5554839 | X3: =Metals!E24 -> 2.6509433 | Y3: =Metals!E25 -> 2.7407459 | Z3: =Metals!E26 -> 2.7619591 | AA3: =Metals!E27 -> 2.5809398
A4: MXene | B4: a (A) | C4: Family | D4: =Metals!A4 -> Ni | E4: =Metals!A5 -> Co | F4: =Metals!A6 -> Cu | G4: =Metals!A7 -> Rh | H4: =Metals!A8 -> Ir | I4: =Metals!A9 -> Pd | J4: =Metals!A10 -> Pt | K4: =Metals!A11 -> Al | L4: =Metals!A12 -> Au | M4: =Metals!A13 -> Ag | N4: =Metals!A14 -> Pb | O4: =Metals!A15 -> Ni3Al | P4: =Metals!A16 -> Ni3Ga | Q4: =Metals!A17 -> Ni3Si | R4: =Metals!A18 -> Ni3Fe | S4: =Metals!A19 -> Ni3Mn | T4: =Metals!A20 -> Ni3Pt | U4: =Metals!A21 -> Ni3Ti | V4: =Metals!A22 -> Ni3(Al,Ti) | W4: =Metals!A23 -> Co3Ti | X4: =Metals!A24 -> Cu3Au | Y4: =Metals!A25 -> Pt3Al | Z4: =Metals!A26 -> Pt3Ti | AA4: =Metals!A27 -> Fe3Al
A5: =MXenes!A4 -> Ti2C | B5: =MXenes!D4 -> 3.039 | C5: =MXenes!B4 -> single M2C | D5: =100*($B5-D$3)/D$3 -> 21.9544 | E5: =100*($B5-E$3)/E$3 -> 21.249084 | F5: =100*($B5-F$3)/F$3 -> 18.891118 | G5: =100*($B5-G$3)/G$3 -> 12.998765 | H5: =100*($B5-H$3)/H$3 -> 11.939236 | I5: =100*($B5-I$3)/I$3 -> 10.463285 | J5: =100*($B5-J$3)/J$3 -> 9.5286581 | K5: =100*($B5-K$3)/K$3 -> 6.1288773 | ... AA5: =100*($B5-AA$3)/AA$3 -> 17.747809
A6: =MXenes!A5 -> V2C | B6: =MXenes!D5 -> 2.881 | C6: =MXenes!B5 -> single M2C | D6: =100*($B6-D$3)/D$3 -> 15.613895 | E6: =100*($B6-E$3)/E$3 -> 14.945248 | F6: =100*($B6-F$3)/F$3 -> 12.709875 | G6: =100*($B6-G$3)/G$3 -> 7.12387 | H6: =100*($B6-H$3)/H$3 -> 6.1194268 | I6: =100*($B6-I$3)/I$3 -> 4.7202116 | J6: =100*($B6-J$3)/J$3 -> 3.834177 | K6: =100*($B6-K$3)/K$3 -> 0.61115353 | ... AA6: =100*($B6-AA$3)/AA$3 -> 11.626007
A7: =MXenes!A6 -> Cr2C | B7: =MXenes!D6 -> 2.825 | C7: =MXenes!B6 -> single M2C | D7: =100*($B7-D$3)/D$3 -> 13.366627 | E7: =100*($B7-E$3)/E$3 -> 12.710978 | F7: =100*($B7-F$3)/F$3 -> 10.519055 | G7: =100*($B7-G$3)/G$3 -> 5.0416289 | H7: =100*($B7-H$3)/H$3 -> 4.0567097 | I7: =100*($B7-I$3)/I$3 -> 2.6846921 | J7: =100*($B7-J$3)/J$3 -> 1.81588 | K7: =100*($B7-K$3)/K$3 -> -1.3444954 | ... AA7: =100*($B7-AA$3)/AA$3 -> 9.4562552
A8: =MXenes!A7 -> Zr2C | B8: =MXenes!D7 -> 3.28 | C8: =MXenes!B7 -> single M2C | D8: =100*($B8-D$3)/D$3 -> 31.625677 | E8: =100*($B8-E$3)/E$3 -> 30.864427 | F8: =100*($B8-F$3)/F$3 -> 28.319469 | G8: =100*($B8-G$3)/G$3 -> 21.959838 | H8: =100*($B8-H$3)/H$3 -> 20.816286 | I8: =100*($B8-I$3)/I$3 -> 19.223288 | J8: =100*($B8-J$3)/J$3 -> 18.214544 | K8: =100*($B8-K$3)/K$3 -> 14.545152 | ... AA8: =100*($B8-AA$3)/AA$3 -> 27.085493
A9: =MXenes!A8 -> Nb2C | B9: =MXenes!D8 -> 3.104 | C9: =MXenes!B8 -> single M2C | D9: =100*($B9-D$3)/D$3 -> 24.562836 | E9: =100*($B9-E$3)/E$3 -> 23.842433 | F9: =100*($B9-F$3)/F$3 -> 21.434034 | G9: =100*($B9-G$3)/G$3 -> 15.415652 | H9: =100*($B9-H$3)/H$3 -> 14.333461 | I9: =100*($B9-I$3)/I$3 -> 12.825941 | J9: =100*($B9-J$3)/J$3 -> 11.871324 | K9: =100*($B9-K$3)/K$3 -> 8.398827 | ... AA9: =100*($B9-AA$3)/AA$3 -> 20.266271
A10: =MXenes!A9 -> Mo2C | B10: =MXenes!D9 -> 2.848 | C10: =MXenes!B9 -> single M2C | D10: =100*($B10-D$3)/D$3 -> 14.289612 | E10: =100*($B10-E$3)/E$3 -> 13.628625 | F10: =100*($B10-F$3)/F$3 -> 11.418856 | G10: =100*($B10-G$3)/G$3 -> 5.8968351 | H10: =100*($B10-H$3)/H$3 -> 4.9038971 | I10: =100*($B10-I$3)/I$3 -> 3.520709 | J10: =100*($B10-J$3)/J$3 -> 2.6448234 | K10: =100*($B10-K$3)/K$3 -> -0.54128246 | ... AA10: =100*($B10-AA$3)/AA$3 -> 10.347403
A11: =MXenes!A10 -> Hf2C | B11: =MXenes!D10 -> 3.195 | C11: =MXenes!B10 -> single M2C | D11: =100*($B11-D$3)/D$3 -> 28.214646 | E11: =100*($B11-E$3)/E$3 -> 27.473123 | F11: =100*($B11-F$3)/F$3 -> 24.994117 | G11: =100*($B11-G$3)/G$3 -> 18.799294 | H11: =100*($B11-H$3)/H$3 -> 17.685376 | I11: =100*($B11-I$3)/I$3 -> 16.133661 | J11: =100*($B11-J$3)/J$3 -> 15.151057 | K11: =100*($B11-K$3)/K$3 -> 11.576757 | ... AA11: =100*($B11-AA$3)/AA$3 -> 23.792119
A12: =MXenes!A11 -> Ta2C | B12: =MXenes!D11 -> 3.067 | C12: =MXenes!B11 -> single M2C | D12: =100*($B12-D$3)/D$3 -> 23.078034 | E12: =100*($B12-E$3)/E$3 -> 22.366219 | F12: =100*($B12-F$3)/F$3 -> 19.986528 | G12: =100*($B12-G$3)/G$3 -> 14.039885 | H12: =100*($B12-H$3)/H$3 -> 12.970594 | I12: =100*($B12-I$3)/I$3 -> 11.481044 | J12: =100*($B12-J$3)/J$3 -> 10.537807 | K12: =100*($B12-K$3)/K$3 -> 7.1067018 | ... AA12: =100*($B12-AA$3)/AA$3 -> 18.832685
A13: =MXenes!A12 -> W2C | B13: =MXenes!D12 -> 2.847 | C13: =MXenes!B12 -> single M2C | D13: =100*($B13-D$3)/D$3 -> 14.249482 | E13: =100*($B13-E$3)/E$3 -> 13.588727 | F13: =100*($B13-F$3)/F$3 -> 11.379734 | G13: =100*($B13-G$3)/G$3 -> 5.8596522 | H13: =100*($B13-H$3)/H$3 -> 4.8670629 | I13: =100*($B13-I$3)/I$3 -> 3.4843605 | J13: =100*($B13-J$3)/J$3 -> 2.6087824 | K13: =100*($B13-K$3)/K$3 -> -0.57620476 | ... AA13: =100*($B13-AA$3)/AA$3 -> 10.308658
A14: =MXenes!A13 -> Ti3C2 | B14: =MXenes!D13 -> 3.104 | C14: =MXenes!B13 -> single M3C2 | D14: =100*($B14-D$3)/D$3 -> 24.562836 | E14: =100*($B14-E$3)/E$3 -> 23.842433 | F14: =100*($B14-F$3)/F$3 -> 21.434034 | G14: =100*($B14-G$3)/G$3 -> 15.415652 | H14: =100*($B14-H$3)/H$3 -> 14.333461 | I14: =100*($B14-I$3)/I$3 -> 12.825941 | J14: =100*($B14-J$3)/J$3 -> 11.871324 | K14: =100*($B14-K$3)/K$3 -> 8.398827 | ... AA14: =100*($B14-AA$3)/AA$3 -> 20.266271
A15: =MXenes!A14 -> V3C2 | B15: =MXenes!D14 -> 2.96 | C15: =MXenes!B14 -> single M3C2 | D15: =100*($B15-D$3)/D$3 -> 18.784148 | E15: =100*($B15-E$3)/E$3 -> 18.097166 | F15: =100*($B15-F$3)/F$3 -> 15.800496 | G15: =100*($B15-G$3)/G$3 -> 10.061317 | H15: =100*($B15-H$3)/H$3 -> 9.0293313 | I15: =100*($B15-I$3)/I$3 -> 7.5917481 | J15: =100*($B15-J$3)/J$3 -> 6.6814176 | K15: =100*($B15-K$3)/K$3 -> 3.3700154 | ... AA15: =100*($B15-AA$3)/AA$3 -> 14.686908
A16: =MXenes!A15 -> Nb3C2 | B16: =MXenes!D15 -> 3.153 | C16: =MXenes!B15 -> single M3C2 | D16: =100*($B16-D$3)/D$3 -> 26.529195 | E16: =100*($B16-E$3)/E$3 -> 25.79742 | F16: =100*($B16-F$3)/F$3 -> 23.351002 | G16: =100*($B16-G$3)/G$3 -> 17.237613 | H16: =100*($B16-H$3)/H$3 -> 16.138338 | I16: =100*($B16-I$3)/I$3 -> 14.607021 | J16: =100*($B16-J$3)/J$3 -> 13.637334 | K16: =100*($B16-K$3)/K$3 -> 10.11002 | ... AA16: =100*($B16-AA$3)/AA$3 -> 22.164804
... A50: =MXenes!A49 -> Ti3C2Tx | B50: =MXenes!D49 -> 3.0505 | C50: =MXenes!B49 -> experimental | D50: =100*($B50-D$3)/D$3 -> 22.415893 | E50: =100*($B50-E$3)/E$3 -> 21.707907 | F50: =100*($B50-F$3)/F$3 -> 19.341018 | G50: =100*($B50-G$3)/G$3 -> 13.426368 | H50: =100*($B50-H$3)/H$3 -> 12.362829 | I50: =100*($B50-I$3)/I$3 -> 10.881293 | J50: =100*($B50-J$3)/J$3 -> 9.9431298 | K50: =100*($B50-K$3)/K$3 -> 6.5304838 | ... AA50: =100*($B50-AA$3)/AA$3 -> 18.193383

Sheet AbsStrain
A1: Absolute strain |delta| (%)
A2: Row 3 is a_111 (A). Column B is a_MXene (A). L12 metals start after Pb. Formulas read Metals and MXenes.
A3: a_111 (A) | D3: =Metals!E4 -> 2.491915 | E3: =Metals!E5 -> 2.5064107 | F3: =Metals!E6 -> 2.5561203 | G3: =Metals!E7 -> 2.6894099 | H3: =Metals!E8 -> 2.7148658 | I3: =Metals!E9 -> 2.7511404 | J3: =Metals!E10 -> 2.7746163 | K3: =Metals!E11 -> 2.8634996 | L3: =Metals!E12 -> 2.8837229 | M3: =Metals!E13 -> 2.8887433 | N3: =Metals!E14 -> 3.50032 | O3: =Metals!E15 -> 2.5257854 | P3: =Metals!E16 -> 2.5286138 | Q3: =Metals!E17 -> 2.4777022 | R3: =Metals!E18 -> 2.5137646 | S3: =Metals!E19 -> 2.5378062 | T3: =Metals!E20 -> 2.5781113 | U3: =Metals!E21 -> 2.5526555 | V3: =Metals!E22 -> 2.5314423 | W3: =Metals!E23 -> 2.5554839 | X3: =Metals!E24 -> 2.6509433 | Y3: =Metals!E25 -> 2.7407459 | Z3: =Metals!E26 -> 2.7619591 | AA3: =Metals!E27 -> 2.5809398
A4: MXene | B4: a (A) | C4: Family | D4: =Metals!A4 -> Ni | E4: =Metals!A5 -> Co | F4: =Metals!A6 -> Cu | G4: =Metals!A7 -> Rh | H4: =Metals!A8 -> Ir | I4: =Metals!A9 -> Pd | J4: =Metals!A10 -> Pt | K4: =Metals!A11 -> Al | L4: =Metals!A12 -> Au | M4: =Metals!A13 -> Ag | N4: =Metals!A14 -> Pb | O4: =Metals!A15 -> Ni3Al | P4: =Metals!A16 -> Ni3Ga | Q4: =Metals!A17 -> Ni3Si | R4: =Metals!A18 -> Ni3Fe | S4: =Metals!A19 -> Ni3Mn | T4: =Metals!A20 -> Ni3Pt | U4: =Metals!A21 -> Ni3Ti | V4: =Metals!A22 -> Ni3(Al,Ti) | W4: =Metals!A23 -> Co3Ti | X4: =Metals!A24 -> Cu3Au | Y4: =Metals!A25 -> Pt3Al | Z4: =Metals!A26 -> Pt3Ti | AA4: =Metals!A27 -> Fe3Al
A5: =MXenes!A4 -> Ti2C | B5: =MXenes!D4 -> 3.039 | C5: =MXenes!B4 -> single M2C | D5: =ABS(100*($B5-D$3)/D$3) -> 21.9544 | E5: =ABS(100*($B5-E$3)/E$3) -> 21.249084 | F5: =ABS(100*($B5-F$3)/F$3) -> 18.891118 | G5: =ABS(100*($B5-G$3)/G$3) -> 12.998765 | H5: =ABS(100*($B5-H$3)/H$3) -> 11.939236 | I5: =ABS(100*($B5-I$3)/I$3) -> 10.463285 | J5: =ABS(100*($B5-J$3)/J$3) -> 9.5286581 | K5: =ABS(100*($B5-K$3)/K$3) -> 6.1288773 | ... AA5: =ABS(100*($B5-AA$3)/AA$3) -> 17.747809
A6: =MXenes!A5 -> V2C | B6: =MXenes!D5 -> 2.881 | C6: =MXenes!B5 -> single M2C | D6: =ABS(100*($B6-D$3)/D$3) -> 15.613895 | E6: =ABS(100*($B6-E$3)/E$3) -> 14.945248 | F6: =ABS(100*($B6-F$3)/F$3) -> 12.709875 | G6: =ABS(100*($B6-G$3)/G$3) -> 7.12387 | H6: =ABS(100*($B6-H$3)/H$3) -> 6.1194268 | I6: =ABS(100*($B6-I$3)/I$3) -> 4.7202116 | J6: =ABS(100*($B6-J$3)/J$3) -> 3.834177 | K6: =ABS(100*($B6-K$3)/K$3) -> 0.61115353 | ... AA6: =ABS(100*($B6-AA$3)/AA$3) -> 11.626007
A7: =MXenes!A6 -> Cr2C | B7: =MXenes!D6 -> 2.825 | C7: =MXenes!B6 -> single M2C | D7: =ABS(100*($B7-D$3)/D$3) -> 13.366627 | E7: =ABS(100*($B7-E$3)/E$3) -> 12.710978 | F7: =ABS(100*($B7-F$3)/F$3) -> 10.519055 | G7: =ABS(100*($B7-G$3)/G$3) -> 5.0416289 | H7: =ABS(100*($B7-H$3)/H$3) -> 4.0567097 | I7: =ABS(100*($B7-I$3)/I$3) -> 2.6846921 | J7: =ABS(100*($B7-J$3)/J$3) -> 1.81588 | K7: =ABS(100*($B7-K$3)/K$3) -> 1.3444954 | ... AA7: =ABS(100*($B7-AA$3)/AA$3) -> 9.4562552
A8: =MXenes!A7 -> Zr2C | B8: =MXenes!D7 -> 3.28 | C8: =MXenes!B7 -> single M2C | D8: =ABS(100*($B8-D$3)/D$3) -> 31.625677 | E8: =ABS(100*($B8-E$3)/E$3) -> 30.864427 | F8: =ABS(100*($B8-F$3)/F$3) -> 28.319469 | G8: =ABS(100*($B8-G$3)/G$3) -> 21.959838 | H8: =ABS(100*($B8-H$3)/H$3) -> 20.816286 | I8: =ABS(100*($B8-I$3)/I$3) -> 19.223288 | J8: =ABS(100*($B8-J$3)/J$3) -> 18.214544 | K8: =ABS(100*($B8-K$3)/K$3) -> 14.545152 | ... AA8: =ABS(100*($B8-AA$3)/AA$3) -> 27.085493
A9: =MXenes!A8 -> Nb2C | B9: =MXenes!D8 -> 3.104 | C9: =MXenes!B8 -> single M2C | D9: =ABS(100*($B9-D$3)/D$3) -> 24.562836 | E9: =ABS(100*($B9-E$3)/E$3) -> 23.842433 | F9: =ABS(100*($B9-F$3)/F$3) -> 21.434034 | G9: =ABS(100*($B9-G$3)/G$3) -> 15.415652 | H9: =ABS(100*($B9-H$3)/H$3) -> 14.333461 | I9: =ABS(100*($B9-I$3)/I$3) -> 12.825941 | J9: =ABS(100*($B9-J$3)/J$3) -> 11.871324 | K9: =ABS(100*($B9-K$3)/K$3) -> 8.398827 | ... AA9: =ABS(100*($B9-AA$3)/AA$3) -> 20.266271
A10: =MXenes!A9 -> Mo2C | B10: =MXenes!D9 -> 2.848 | C10: =MXenes!B9 -> single M2C | D10: =ABS(100*($B10-D$3)/D$3) -> 14.289612 | E10: =ABS(100*($B10-E$3)/E$3) -> 13.628625 | F10: =ABS(100*($B10-F$3)/F$3) -> 11.418856 | G10: =ABS(100*($B10-G$3)/G$3) -> 5.8968351 | H10: =ABS(100*($B10-H$3)/H$3) -> 4.9038971 | I10: =ABS(100*($B10-I$3)/I$3) -> 3.520709 | J10: =ABS(100*($B10-J$3)/J$3) -> 2.6448234 | K10: =ABS(100*($B10-K$3)/K$3) -> 0.54128246 | ... AA10: =ABS(100*($B10-AA$3)/AA$3) -> 10.347403
A11: =MXenes!A10 -> Hf2C | B11: =MXenes!D10 -> 3.195 | C11: =MXenes!B10 -> single M2C | D11: =ABS(100*($B11-D$3)/D$3) -> 28.214646 | E11: =ABS(100*($B11-E$3)/E$3) -> 27.473123 | F11: =ABS(100*($B11-F$3)/F$3) -> 24.994117 | G11: =ABS(100*($B11-G$3)/G$3) -> 18.799294 | H11: =ABS(100*($B11-H$3)/H$3) -> 17.685376 | I11: =ABS(100*($B11-I$3)/I$3) -> 16.133661 | J11: =ABS(100*($B11-J$3)/J$3) -> 15.151057 | K11: =ABS(100*($B11-K$3)/K$3) -> 11.576757 | ... AA11: =ABS(100*($B11-AA$3)/AA$3) -> 23.792119
A12: =MXenes!A11 -> Ta2C | B12: =MXenes!D11 -> 3.067 | C12: =MXenes!B11 -> single M2C | D12: =ABS(100*($B12-D$3)/D$3) -> 23.078034 | E12: =ABS(100*($B12-E$3)/E$3) -> 22.366219 | F12: =ABS(100*($B12-F$3)/F$3) -> 19.986528 | G12: =ABS(100*($B12-G$3)/G$3) -> 14.039885 | H12: =ABS(100*($B12-H$3)/H$3) -> 12.970594 | I12: =ABS(100*($B12-I$3)/I$3) -> 11.481044 | J12: =ABS(100*($B12-J$3)/J$3) -> 10.537807 | K12: =ABS(100*($B12-K$3)/K$3) -> 7.1067018 | ... AA12: =ABS(100*($B12-AA$3)/AA$3) -> 18.832685
A13: =MXenes!A12 -> W2C | B13: =MXenes!D12 -> 2.847 | C13: =MXenes!B12 -> single M2C | D13: =ABS(100*($B13-D$3)/D$3) -> 14.249482 | E13: =ABS(100*($B13-E$3)/E$3) -> 13.588727 | F13: =ABS(100*($B13-F$3)/F$3) -> 11.379734 | G13: =ABS(100*($B13-G$3)/G$3) -> 5.8596522 | H13: =ABS(100*($B13-H$3)/H$3) -> 4.8670629 | I13: =ABS(100*($B13-I$3)/I$3) -> 3.4843605 | J13: =ABS(100*($B13-J$3)/J$3) -> 2.6087824 | K13: =ABS(100*($B13-K$3)/K$3) -> 0.57620476 | ... AA13: =ABS(100*($B13-AA$3)/AA$3) -> 10.308658
A14: =MXenes!A13 -> Ti3C2 | B14: =MXenes!D13 -> 3.104 | C14: =MXenes!B13 -> single M3C2 | D14: =ABS(100*($B14-D$3)/D$3) -> 24.562836 | E14: =ABS(100*($B14-E$3)/E$3) -> 23.842433 | F14: =ABS(100*($B14-F$3)/F$3) -> 21.434034 | G14: =ABS(100*($B14-G$3)/G$3) -> 15.415652 | H14: =ABS(100*($B14-H$3)/H$3) -> 14.333461 | I14: =ABS(100*($B14-I$3)/I$3) -> 12.825941 | J14: =ABS(100*($B14-J$3)/J$3) -> 11.871324 | K14: =ABS(100*($B14-K$3)/K$3) -> 8.398827 | ... AA14: =ABS(100*($B14-AA$3)/AA$3) -> 20.266271
A15: =MXenes!A14 -> V3C2 | B15: =MXenes!D14 -> 2.96 | C15: =MXenes!B14 -> single M3C2 | D15: =ABS(100*($B15-D$3)/D$3) -> 18.784148 | E15: =ABS(100*($B15-E$3)/E$3) -> 18.097166 | F15: =ABS(100*($B15-F$3)/F$3) -> 15.800496 | G15: =ABS(100*($B15-G$3)/G$3) -> 10.061317 | H15: =ABS(100*($B15-H$3)/H$3) -> 9.0293313 | I15: =ABS(100*($B15-I$3)/I$3) -> 7.5917481 | J15: =ABS(100*($B15-J$3)/J$3) -> 6.6814176 | K15: =ABS(100*($B15-K$3)/K$3) -> 3.3700154 | ... AA15: =ABS(100*($B15-AA$3)/AA$3) -> 14.686908
A16: =MXenes!A15 -> Nb3C2 | B16: =MXenes!D15 -> 3.153 | C16: =MXenes!B15 -> single M3C2 | D16: =ABS(100*($B16-D$3)/D$3) -> 26.529195 | E16: =ABS(100*($B16-E$3)/E$3) -> 25.79742 | F16: =ABS(100*($B16-F$3)/F$3) -> 23.351002 | G16: =ABS(100*($B16-G$3)/G$3) -> 17.237613 | H16: =ABS(100*($B16-H$3)/H$3) -> 16.138338 | I16: =ABS(100*($B16-I$3)/I$3) -> 14.607021 | J16: =ABS(100*($B16-J$3)/J$3) -> 13.637334 | K16: =ABS(100*($B16-K$3)/K$3) -> 10.11002 | ... AA16: =ABS(100*($B16-AA$3)/AA$3) -> 22.164804
... A50: =MXenes!A49 -> Ti3C2Tx | B50: =MXenes!D49 -> 3.0505 | C50: =MXenes!B49 -> experimental | D50: =ABS(100*($B50-D$3)/D$3) -> 22.415893 | E50: =ABS(100*($B50-E$3)/E$3) -> 21.707907 | F50: =ABS(100*($B50-F$3)/F$3) -> 19.341018 | G50: =ABS(100*($B50-G$3)/G$3) -> 13.426368 | H50: =ABS(100*($B50-H$3)/H$3) -> 12.362829 | I50: =ABS(100*($B50-I$3)/I$3) -> 10.881293 | J50: =ABS(100*($B50-J$3)/J$3) -> 9.9431298 | K50: =ABS(100*($B50-K$3)/K$3) -> 6.5304838 | ... AA50: =ABS(100*($B50-AA$3)/AA$3) -> 18.193383

Sheet Best_pairs
A1: Pairs with |strain| <= 4% (1x1)
A2: Ranked from the input lattices. Strain formulas point at the Strain sheet.
A4: Rank | B4: MXene | C4: Family | D4: a_MXene | E4: Metal | F4: Structure | G4: a_111 | H4: strain (%)
A5: 1 | B5: =MXenes!A5 -> V2C | C5: =MXenes!B5 -> single M2C | D5: =MXenes!D5 -> 2.881 | E5: =Metals!A12 -> Au | F5: =Metals!C12 -> FCC | G5: =Metals!E12 -> 2.8837229 | H5: =Strain!L6 -> -0.094422216
A6: 2 | B6: =MXenes!A44 -> Cr2TiCNO2 | C6: =MXenes!B44 -> ordered carbonitride | D6: =MXenes!D44 -> 2.86 | E6: =Metals!A11 -> Al | F6: =Metals!C11 -> FCC | G6: =Metals!E11 -> 2.8634996 | H6: =Strain!K45 -> -0.12221483
A7: 3 | B7: =MXenes!A5 -> V2C | C7: =MXenes!B5 -> single M2C | D7: =MXenes!D5 -> 2.881 | E7: =Metals!A13 -> Ag | F7: =Metals!C13 -> FCC | G7: =Metals!E13 -> 2.8887433 | H7: =Strain!M6 -> -0.26805196
A8: 4 | B8: =MXenes!A39 -> V2TiCNO2 | C8: =MXenes!B39 -> ordered carbonitride | D8: =MXenes!D39 -> 2.9 | E8: =Metals!A13 -> Ag | F8: =Metals!C13 -> FCC | G8: =Metals!E13 -> 2.8887433 | H8: =Strain!M40 -> 0.38967348
A9: 5 | B9: =MXenes!A34 -> Cr2VC2O2 | C9: =MXenes!B34 -> ordered DTM | D9: =MXenes!D34 -> 2.902 | E9: =Metals!A13 -> Ag | F9: =Metals!C13 -> FCC | G9: =Metals!E13 -> 2.8887433 | H9: =Strain!M35 -> 0.45890774
A10: 6 | B10: =MXenes!A9 -> Mo2C | C10: =MXenes!B9 -> single M2C | D10: =MXenes!D9 -> 2.848 | E10: =Metals!A11 -> Al | F10: =Metals!C11 -> FCC | G10: =Metals!E11 -> 2.8634996 | H10: =Strain!K10 -> -0.54128246
A11: 7 | B11: =MXenes!A39 -> V2TiCNO2 | C11: =MXenes!B39 -> ordered carbonitride | D11: =MXenes!D39 -> 2.9 | E11: =Metals!A12 -> Au | F11: =Metals!C12 -> FCC | G11: =Metals!E12 -> 2.8837229 | H11: =Strain!L40 -> 0.56444831
A12: 8 | B12: =MXenes!A12 -> W2C | C12: =MXenes!B12 -> single M2C | D12: =MXenes!D12 -> 2.847 | E12: =Metals!A11 -> Al | F12: =Metals!C11 -> FCC | G12: =Metals!E11 -> 2.8634996 | H12: =Strain!K13 -> -0.57620476
A13: 9 | B13: =MXenes!A5 -> V2C | C13: =MXenes!B5 -> single M2C | D13: =MXenes!D5 -> 2.881 | E13: =Metals!A11 -> Al | F13: =Metals!C11 -> FCC | G13: =Metals!E11 -> 2.8634996 | H13: =Strain!K6 -> 0.61115353
A14: 10 | B14: =MXenes!A32 -> Cr2TiC2O2 | C14: =MXenes!B32 -> ordered DTM | D14: =MXenes!D32 -> 2.907 | E14: =Metals!A13 -> Ag | F14: =Metals!C13 -> FCC | G14: =Metals!E13 -> 2.8887433 | H14: =Strain!M33 -> 0.63199339
A15: 11 | B15: =MXenes!A34 -> Cr2VC2O2 | C15: =MXenes!B34 -> ordered DTM | D15: =MXenes!D34 -> 2.902 | E15: =Metals!A12 -> Au | F15: =Metals!C12 -> FCC | G15: =Metals!E12 -> 2.8837229 | H15: =Strain!L35 -> 0.6338031
A16: 12 | B16: =MXenes!A42 -> Mo2TiCNO2 | C16: =MXenes!B42 -> ordered carbonitride | D16: =MXenes!D42 -> 2.91 | E16: =Metals!A13 -> Ag | F16: =Metals!C13 -> FCC | G16: =Metals!E13 -> 2.8887433 | H16: =Strain!M43 -> 0.73584477
A17: 13 | B17: =MXenes!A32 -> Cr2TiC2O2 | C17: =MXenes!B32 -> ordered DTM | D17: =MXenes!D32 -> 2.907 | E17: =Metals!A12 -> Au | F17: =Metals!C12 -> FCC | G17: =Metals!E12 -> 2.8837229 | H17: =Strain!L33 -> 0.80719008
A18: 14 | B18: =MXenes!A44 -> Cr2TiCNO2 | C18: =MXenes!B44 -> ordered carbonitride | D18: =MXenes!D44 -> 2.86 | E18: =Metals!A12 -> Au | F18: =Metals!C12 -> FCC | G18: =Metals!E12 -> 2.8837229 | H18: =Strain!L45 -> -0.82264753
A19: 15 | B19: =MXenes!A42 -> Mo2TiCNO2 | C19: =MXenes!B42 -> ordered carbonitride | D19: =MXenes!D42 -> 2.91 | E19: =Metals!A12 -> Au | F19: =Metals!C12 -> FCC | G19: =Metals!E12 -> 2.8837229 | H19: =Strain!L43 -> 0.91122227
A20: 16 | B20: =MXenes!A44 -> Cr2TiCNO2 | C20: =MXenes!B44 -> ordered carbonitride | D20: =MXenes!D44 -> 2.86 | E20: =Metals!A13 -> Ag | F20: =Metals!C13 -> FCC | G20: =Metals!E13 -> 2.8887433 | H20: =Strain!M45 -> -0.99501167
A21: 17 | B21: =MXenes!A9 -> Mo2C | C21: =MXenes!B9 -> single M2C | D21: =MXenes!D9 -> 2.848 | E21: =Metals!A12 -> Au | F21: =Metals!C12 -> FCC | G21: =Metals!E12 -> 2.8837229 | H21: =Strain!L10 -> -1.2387763
A22: 18 | B22: =MXenes!A12 -> W2C | C22: =MXenes!B12 -> single M2C | D22: =MXenes!D12 -> 2.847 | E22: =Metals!A12 -> Au | F22: =Metals!C12 -> FCC | G22: =Metals!E12 -> 2.8837229 | H22: =Strain!L13 -> -1.2734537
A23: 19 | B23: =MXenes!A39 -> V2TiCNO2 | C23: =MXenes!B39 -> ordered carbonitride | D23: =MXenes!D39 -> 2.9 | E23: =Metals!A11 -> Al | F23: =Metals!C11 -> FCC | G23: =Metals!E11 -> 2.8634996 | H23: =Strain!K40 -> 1.2746773
A24: 20 | B24: =MXenes!A6 -> Cr2C | C24: =MXenes!B6 -> single M2C | D24: =MXenes!D6 -> 2.825 | E24: =Metals!A11 -> Al | F24: =Metals!C11 -> FCC | G24: =Metals!E11 -> 2.8634996 | H24: =Strain!K7 -> -1.3444954
A25: 21 | B25: =MXenes!A34 -> Cr2VC2O2 | C25: =MXenes!B34 -> ordered DTM | D25: =MXenes!D34 -> 2.902 | E25: =Metals!A11 -> Al | F25: =Metals!C11 -> FCC | G25: =Metals!E11 -> 2.8634996 | H25: =Strain!K35 -> 1.3445219
A26: 22 | B26: =MXenes!A9 -> Mo2C | C26: =MXenes!B9 -> single M2C | D26: =MXenes!D9 -> 2.848 | E26: =Metals!A13 -> Ag | F26: =Metals!C13 -> FCC | G26: =Metals!E13 -> 2.8887433 | H26: =Strain!M10 -> -1.4104172
A27: 23 | B27: =MXenes!A12 -> W2C | C27: =MXenes!B12 -> single M2C | D27: =MXenes!D12 -> 2.847 | E27: =Metals!A13 -> Ag | F27: =Metals!C13 -> FCC | G27: =Metals!E13 -> 2.8887433 | H27: =Strain!M13 -> -1.4450343
A28: 24 | B28: =MXenes!A32 -> Cr2TiC2O2 | C28: =MXenes!B32 -> ordered DTM | D28: =MXenes!D32 -> 2.907 | E28: =Metals!A11 -> Al | F28: =Metals!C11 -> FCC | G28: =Metals!E11 -> 2.8634996 | H28: =Strain!K33 -> 1.5191334
A29: 25 | B29: =MXenes!A42 -> Mo2TiCNO2 | C29: =MXenes!B42 -> ordered carbonitride | D29: =MXenes!D42 -> 2.91 | E29: =Metals!A11 -> Al | F29: =Metals!C11 -> FCC | G29: =Metals!E11 -> 2.8634996 | H29: =Strain!K43 -> 1.6239003
A30: 26 | B30: =MXenes!A6 -> Cr2C | C30: =MXenes!B6 -> single M2C | D30: =MXenes!D6 -> 2.825 | E30: =Metals!A10 -> Pt | F30: =Metals!C10 -> FCC | G30: =Metals!E10 -> 2.7746163 | H30: =Strain!J7 -> 1.81588
A31: 27 | B31: =MXenes!A6 -> Cr2C | C31: =MXenes!B6 -> single M2C | D31: =MXenes!D6 -> 2.825 | E31: =Metals!A12 -> Au | F31: =Metals!C12 -> FCC | G31: =Metals!E12 -> 2.8837229 | H31: =Strain!L7 -> -2.0363564
A32: 28 | B32: =MXenes!A6 -> Cr2C | C32: =MXenes!B6 -> single M2C | D32: =MXenes!D6 -> 2.825 | E32: =Metals!A13 -> Ag | F32: =Metals!C13 -> FCC | G32: =Metals!E13 -> 2.8887433 | H32: =Strain!M7 -> -2.2066112
A33: 29 | B33: =MXenes!A6 -> Cr2C | C33: =MXenes!B6 -> single M2C | D33: =MXenes!D6 -> 2.825 | E33: =Metals!A26 -> Pt3Ti | F33: =Metals!C26 -> L12 | G33: =Metals!E26 -> 2.7619591 | H33: =Strain!Z7 -> 2.2824709
A34: 30 | B34: =MXenes!A14 -> V3C2 | C34: =MXenes!B14 -> single M3C2 | D34: =MXenes!D14 -> 2.96 | E34: =Metals!A13 -> Ag | F34: =Metals!C13 -> FCC | G34: =Metals!E13 -> 2.8887433 | H34: =Strain!M15 -> 2.4667012
A35: 31 | B35: =MXenes!A46 -> (Ti0.5V0.5)2C | C35: =MXenes!B46 -> solid solution | D35: =MXenes!D46 -> 2.96 | E35: =Metals!A13 -> Ag | F35: =Metals!C13 -> FCC | G35: =Metals!E13 -> 2.8887433 | H35: =Strain!M47 -> 2.4667012
A36: 32 | B36: =MXenes!A12 -> W2C | C36: =MXenes!B12 -> single M2C | D36: =MXenes!D12 -> 2.847 | E36: =Metals!A10 -> Pt | F36: =Metals!C10 -> FCC | G36: =Metals!E10 -> 2.7746163 | H36: =Strain!J13 -> 2.6087824
A37: 33 | B37: =MXenes!A9 -> Mo2C | C37: =MXenes!B9 -> single M2C | D37: =MXenes!D9 -> 2.848 | E37: =Metals!A10 -> Pt | F37: =Metals!C10 -> FCC | G37: =Metals!E10 -> 2.7746163 | H37: =Strain!J10 -> 2.6448234
A38: 34 | B38: =MXenes!A14 -> V3C2 | C38: =MXenes!B14 -> single M3C2 | D38: =MXenes!D14 -> 2.96 | E38: =Metals!A12 -> Au | F38: =Metals!C12 -> FCC | G38: =Metals!E12 -> 2.8837229 | H38: =Strain!L15 -> 2.6450921
A39: 35 | B39: =MXenes!A46 -> (Ti0.5V0.5)2C | C39: =MXenes!B46 -> solid solution | D39: =MXenes!D46 -> 2.96 | E39: =Metals!A12 -> Au | F39: =Metals!C12 -> FCC | G39: =Metals!E12 -> 2.8837229 | H39: =Strain!L47 -> 2.6450921
A40: 36 | B40: =MXenes!A6 -> Cr2C | C40: =MXenes!B6 -> single M2C | D40: =MXenes!D6 -> 2.825 | E40: =Metals!A9 -> Pd | F40: =Metals!C9 -> FCC | G40: =Metals!E9 -> 2.7511404 | H40: =Strain!I7 -> 2.6846921
A41: 37 | B41: =MXenes!A6 -> Cr2C | C41: =MXenes!B6 -> single M2C | D41: =MXenes!D6 -> 2.825 | E41: =Metals!A25 -> Pt3Al | F41: =Metals!C25 -> L12 | G41: =Metals!E25 -> 2.7407459 | H41: =Strain!Y7 -> 3.0741309
...
